---
title: 输出什么?
pubDatetime: 2021-07-03T22:35:59.000Z
author: caorushizi
tags:
  - 选择题
postSlug: b2a2be3541fc8b871f3c603f3670f1f1
description: >-
  const promise1 = Promise.resolve('First') const promise2 =
  Promise.resolve('Second') const promise3 = Promise.reject('Third') const
  promise4 = Promise.resolve('Fourth') const runPromises = async () =>
difficulty: 0.5
questionNumber: 157
source: https://fe.ecool.fun/topic/849fda3c-2d6b-4192-8ea3-d8bc23541599
---

```javascript
const promise1 = Promise.resolve("First");
const promise2 = Promise.resolve("Second");
const promise3 = Promise.reject("Third");
const promise4 = Promise.resolve("Fourth");

const runPromises = async () => {
  const res1 = await Promise.all([promise1, promise2]);
  const res2 = await Promise.all([promise3, promise4]);
  return [res1, res2];
};

runPromises()
  .then(res => console.log(res))
  .catch(err => console.log(err));
```

`Promise.all` 方法可以并行式运行 promise。如果其中一个 promise 失败了，`Promise.all` 方法会带上被 reject 的 promise 的值*rejects*。在这个例子中， `promise3` 带着 `"Third"` 值 reject。我们在调用 `runPromises` 时在 `runPromises` 函数内部的 `catch` 方法去捕获任意 error 从而捕获到被 reject 的值。因为 `promise3` 带着 `"Third"` 被 reject，所以只有 `"Third"` 打印。
